2025-04-14 18:28:16,892 - app - INFO - Category Salary updated successfully - [in /home/patrick/goalifai/app/api/v1/categories.py:71]
2025-06-23 12:04:33,328 - app - INFO - Category type Income created successfully - [in /home/patrick/goalifai/app/api/v1/category_types.py:27]
2025-06-23 12:05:57,532 - app - ERROR - Error creating category type: 415 Unsupported Media Type: Did not attempt to load JSON data because the request Content-Type was not 'application/json'. - [in /home/patrick/goalifai/app/api/v1/category_types.py:33]
2025-06-23 12:06:32,965 - app - ERROR - Error fetching category types: type object 'CategoriesType' has no attribute 'get_all_category_types' - [in /home/patrick/goalifai/app/api/v1/category_types.py:14]
2025-06-23 12:07:06,146 - app - ERROR - Error fetching category types: type object 'CategoriesType' has no attribute 'get_all_category_types' - [in /home/patrick/goalifai/app/api/v1/category_types.py:14]
2025-06-23 12:09:46,314 - app - INFO - Category type Expense created successfully - [in /home/patrick/goalifai/app/api/v1/category_types.py:27]
2025-06-23 13:06:28,084 - app - ERROR - Error updating category type: 415 Unsupported Media Type: Did not attempt to load JSON data because the request Content-Type was not 'application/json'. - [in /home/patrick/goalifai/app/api/v1/category_types.py:52]
2025-06-23 13:06:39,620 - app - ERROR - Error updating category type: (psycopg2.errors.UniqueViolation) duplicate key value violates unique constraint "categories_type_name_key"
DETAIL:  Key (name)=(Income) already exists.

[SQL: UPDATE categories_type SET name=%(name)s WHERE categories_type.type_id = %(categories_type_type_id)s::UUID]
[parameters: {'name': 'Income', 'categories_type_type_id': UUID('5330c279-9760-4db2-901b-c1e0cbd00c95')}]
(Background on this error at: https://sqlalche.me/e/20/gkpj) - [in /home/patrick/goalifai/app/api/v1/category_types.py:52]
2025-06-23 13:15:11,223 - app - ERROR - Error updating category type: Category type with name 'Income' already exists - [in /home/patrick/goalifai/app/api/v1/category_types.py:59]
2025-06-23 13:18:55,089 - app - ERROR - Error updating category type: 'name' - [in /home/patrick/goalifai/app/api/v1/category_types.py:61]
2025-06-23 13:23:23,083 - app - INFO - Category type 5330c279-9760-4db2-901b-c1e0cbd00c95 updated successfully - [in /home/patrick/goalifai/app/api/v1/category_types.py:53]
2025-06-23 13:23:23,084 - app - ERROR - Error updating category type: 'dict' object has no attribute 'to_dict' - [in /home/patrick/goalifai/app/api/v1/category_types.py:59]
2025-06-23 13:43:25,140 - app - INFO - Category type 5330c279-9760-4db2-901b-c1e0cbd00c95 updated successfully - [in /home/patrick/goalifai/app/api/v1/category_types.py:57]
2025-06-23 13:43:57,116 - app - WARNING - Validation error updating category type 5330c279-9760-4db2-901b-c1e0cbd00c95: Category type with name 'Income' already exists - [in /home/patrick/goalifai/app/api/v1/category_types.py:66]
2025-07-15 21:57:40,100 - app - ERROR - An error occurred: Mapper 'Mapper[User(users)]' has no property 'education'.  If this property was indicated from other mappers or configure events, ensure registry.configure() has been called. - [in /home/patrick/goalifai/app/api/v1/degree.py:28]
2025-07-15 22:07:56,809 - app - ERROR - An error occurred: Mapper 'Mapper[User(users)]' has no property 'education'.  If this property was indicated from other mappers or configure events, ensure registry.configure() has been called. - [in /home/patrick/goalifai/app/api/v1/degree.py:28]
2025-07-15 22:29:45,111 - app - ERROR - An error occurred: Could not determine join condition between parent/child tables on relationship Degree.educations - there are no foreign keys linking these tables.  Ensure that referencing columns are associated with a ForeignKey or ForeignKeyConstraint, or specify a 'primaryjoin' expression. - [in /home/patrick/goalifai/app/api/v1/degree.py:28]
2025-07-15 22:36:05,241 - app - ERROR - An error occurred: Mapper 'Mapper[User(users)]' has no property 'education'.  If this property was indicated from other mappers or configure events, ensure registry.configure() has been called. - [in /home/patrick/goalifai/app/api/v1/degree.py:28]
2025-07-15 22:39:35,364 - app - ERROR - An error occurred: Mapper 'Mapper[Degree(degrees)]' has no property 'education'.  If this property was indicated from other mappers or configure events, ensure registry.configure() has been called. - [in /home/patrick/goalifai/app/api/v1/degree.py:28]
2025-07-15 22:42:41,736 - app - INFO - Degree High school created successfully - [in /home/patrick/goalifai/app/api/v1/degree.py:28]
2025-07-15 22:54:47,558 - app - INFO - Degree high school deleted successfully - [in /home/patrick/goalifai/app/api/v1/degree.py:74]
2025-07-15 23:23:15,035 - app - ERROR - An error occurred: 'User' object has no attribute 'education_level' - [in /home/patrick/goalifai/app/api/v1/users.py:88]
2025-07-15 23:23:15,036 - app - ERROR - Traceback (most recent call last):
  File "/home/patrick/goalifai/app/api/v1/users.py", line 77, in users_list
    "education_level": user.education_level,
                       ^^^^^^^^^^^^^^^^^^^^
AttributeError: 'User' object has no attribute 'education_level'
 - [in /home/patrick/goalifai/app/api/v1/users.py:89]
2025-07-15 23:30:04,374 - app - ERROR - An error occurred: Education.create_education() got an unexpected keyword argument 'degree_id' - [in /home/patrick/goalifai/app/api/v1/education.py:50]
2025-07-15 23:32:54,653 - app - ERROR - Error creating education record: 'str' object has no attribute '_sa_instance_state' - [in /home/patrick/goalifai/app/models/users_model.py:379]
2025-07-15 23:32:54,653 - app - ERROR - An error occurred while creating the education record - [in /home/patrick/goalifai/app/api/v1/education.py:42]
2025-07-15 23:36:20,870 - app - ERROR - Error creating education record: 'str' object has no attribute '_sa_instance_state' - [in /home/patrick/goalifai/app/models/users_model.py:379]
2025-07-15 23:36:20,870 - app - ERROR - An error occurred while creating the education record - [in /home/patrick/goalifai/app/api/v1/education.py:42]
2025-07-15 23:38:21,000 - app - ERROR - Error creating education record: 'str' object has no attribute '_sa_instance_state' - [in /home/patrick/goalifai/app/models/users_model.py:379]
2025-07-15 23:38:21,000 - app - ERROR - An error occurred while creating the education record - [in /home/patrick/goalifai/app/api/v1/education.py:42]
2025-07-15 23:44:03,785 - app - ERROR - Error creating education record: 'str' object has no attribute '_sa_instance_state' - [in /home/patrick/goalifai/app/models/users_model.py:379]
2025-07-15 23:44:03,785 - app - ERROR - An error occurred while creating the education record - [in /home/patrick/goalifai/app/api/v1/education.py:42]
2025-07-15 23:44:49,133 - app - ERROR - Error creating education record: (psycopg2.ProgrammingError) can't adapt type 'User'
[SQL: INSERT INTO education (education_id, user_id, institution_name, degree_id, field_of_study, start_date, end_date, created_at, updated_at) VALUES (%(education_id)s::UUID, %(user_id)s::UUID, %(institution_name)s, %(degree_id)s::UUID, %(field_of_study)s, %(start_date)s, %(end_date)s, %(created_at)s, %(updated_at)s)]
[parameters: {'education_id': UUID('dd5f32f3-bed7-4526-b883-aa1b5c3b0390'), 'user_id': 
        user_id: b53164c4-7510-4c68-9641-499353facd90
        email: abc@example.com
        first_name: Jane
        last_name: Doe
        date_of_ ... (134 characters truncated) ... mated_monthly_expenses: None
        savings: 0
        created_at: 2025-03-19 22:25:41.841054
        updated_at: 2025-03-19 22:25:41.841058
        , 'institution_name': 'Harvard university', 'degree_id': UUID('390222d6-0419-4679-8e4f-d2885257e512'), 'field_of_study': 'Reasearch and alchaeology', 'start_date': '2019-04-09', 'end_date': None, 'created_at': datetime.datetime(2025, 7, 15, 21, 44, 49, 131202, tzinfo=datetime.timezone.utc), 'updated_at': datetime.datetime(2025, 7, 15, 21, 44, 49, 131205, tzinfo=datetime.timezone.utc)}]
(Background on this error at: https://sqlalche.me/e/20/f405) - [in /home/patrick/goalifai/app/models/users_model.py:379]
2025-07-15 23:44:49,133 - app - ERROR - An error occurred while creating the education record - [in /home/patrick/goalifai/app/api/v1/education.py:42]
2025-07-15 23:46:17,680 - app - INFO - Education record for user b53164c4-7510-4c68-9641-499353facd90 created successfully - [in /home/patrick/goalifai/app/api/v1/education.py:44]
2025-07-15 23:46:17,694 - app - ERROR - An error occurred: Object of type Degree is not JSON serializable - [in /home/patrick/goalifai/app/api/v1/education.py:51]
2025-07-15 23:46:17,700 - app - ERROR - Traceback (most recent call last):
  File "/home/patrick/goalifai/app/api/v1/education.py", line 45, in create_education
    return jsonify({
           ^^^^^^^^^
  File "/home/patrick/goalifai/local-engine/lib/python3.12/site-packages/flask/json/__init__.py", line 170, in jsonify
    return current_app.json.response(*args, **kwargs)  # type: ignore[return-value]
           ^^^^^^^^^^^^^^^^^^^^^^^^^^^^^^^^^^^^^^^^^^
  File "/home/patrick/goalifai/local-engine/lib/python3.12/site-packages/flask/json/provider.py", line 214, in response
    f"{self.dumps(obj, **dump_args)}\n", mimetype=self.mimetype
       ^^^^^^^^^^^^^^^^^^^^^^^^^^^^
  File "/home/patrick/goalifai/local-engine/lib/python3.12/site-packages/flask/json/provider.py", line 179, in dumps
    return json.dumps(obj, **kwargs)
           ^^^^^^^^^^^^^^^^^^^^^^^^^
  File "/usr/lib/python3.12/json/__init__.py", line 238, in dumps
    **kw).encode(obj)
          ^^^^^^^^^^^
  File "/usr/lib/python3.12/json/encoder.py", line 202, in encode
    chunks = list(chunks)
             ^^^^^^^^^^^^
  File "/usr/lib/python3.12/json/encoder.py", line 432, in _iterencode
    yield from _iterencode_dict(o, _current_indent_level)
  File "/usr/lib/python3.12/json/encoder.py", line 406, in _iterencode_dict
    yield from chunks
  File "/usr/lib/python3.12/json/encoder.py", line 406, in _iterencode_dict
    yield from chunks
  File "/usr/lib/python3.12/json/encoder.py", line 439, in _iterencode
    o = _default(o)
        ^^^^^^^^^^^
  File "/home/patrick/goalifai/local-engine/lib/python3.12/site-packages/flask/json/provider.py", line 121, in _default
    raise TypeError(f"Object of type {type(o).__name__} is not JSON serializable")
TypeError: Object of type Degree is not JSON serializable
 - [in /home/patrick/goalifai/app/api/v1/education.py:52]
2025-07-15 23:47:21,104 - app - ERROR - Error creating education record: 'str' object has no attribute '_sa_instance_state' - [in /home/patrick/goalifai/app/models/users_model.py:379]
2025-07-15 23:47:21,105 - app - ERROR - An error occurred while creating the education record - [in /home/patrick/goalifai/app/api/v1/education.py:42]
2025-07-15 23:48:07,879 - app - ERROR - Error creating education record: (psycopg2.ProgrammingError) can't adapt type 'User'
[SQL: INSERT INTO education (education_id, user_id, institution_name, degree_id, field_of_study, start_date, end_date, created_at, updated_at) VALUES (%(education_id)s::UUID, %(user_id)s::UUID, %(institution_name)s, %(degree_id)s::UUID, %(field_of_study)s, %(start_date)s, %(end_date)s, %(created_at)s, %(updated_at)s)]
[parameters: {'education_id': UUID('776faa2c-cf6a-4652-8535-9f70d02e22fe'), 'user_id': 
        user_id: b53164c4-7510-4c68-9641-499353facd90
        email: abc@example.com
        first_name: Jane
        last_name: Doe
        date_of_ ... (134 characters truncated) ... mated_monthly_expenses: None
        savings: 0
        created_at: 2025-03-19 22:25:41.841054
        updated_at: 2025-03-19 22:25:41.841058
        , 'institution_name': 'Harvard university', 'degree_id': UUID('390222d6-0419-4679-8e4f-d2885257e512'), 'field_of_study': 'Reasearch and alchaeology', 'start_date': '2019-04-09', 'end_date': None, 'created_at': datetime.datetime(2025, 7, 15, 21, 48, 7, 877263, tzinfo=datetime.timezone.utc), 'updated_at': datetime.datetime(2025, 7, 15, 21, 48, 7, 877266, tzinfo=datetime.timezone.utc)}]
(Background on this error at: https://sqlalche.me/e/20/f405) - [in /home/patrick/goalifai/app/models/users_model.py:379]
2025-07-15 23:48:07,879 - app - ERROR - An error occurred while creating the education record - [in /home/patrick/goalifai/app/api/v1/education.py:42]
2025-07-15 23:51:33,906 - app - ERROR - Error creating education record: 'UUID' object has no attribute '_sa_instance_state' - [in /home/patrick/goalifai/app/models/users_model.py:379]
2025-07-15 23:51:33,906 - app - ERROR - An error occurred while creating the education record - [in /home/patrick/goalifai/app/api/v1/education.py:42]
2025-07-15 23:51:50,893 - app - ERROR - Error creating education record: 'UUID' object has no attribute '_sa_instance_state' - [in /home/patrick/goalifai/app/models/users_model.py:379]
2025-07-15 23:51:50,894 - app - ERROR - An error occurred while creating the education record - [in /home/patrick/goalifai/app/api/v1/education.py:42]
2025-07-15 23:52:41,590 - app - ERROR - Error creating education record: Neither 'InstrumentedAttribute' object nor 'Comparator' object associated with Education.user has an attribute 'user_id' - [in /home/patrick/goalifai/app/models/users_model.py:379]
2025-07-15 23:52:41,591 - app - ERROR - An error occurred while creating the education record - [in /home/patrick/goalifai/app/api/v1/education.py:42]
2025-07-15 23:53:40,532 - app - ERROR - Error creating education record: type object 'User' has no attribute 'user' - [in /home/patrick/goalifai/app/models/users_model.py:379]
2025-07-15 23:53:40,533 - app - ERROR - An error occurred while creating the education record - [in /home/patrick/goalifai/app/api/v1/education.py:42]
2025-07-15 23:54:22,246 - app - ERROR - Error creating education record: Neither 'InstrumentedAttribute' object nor 'Comparator' object associated with User.education has an attribute 'user_id' - [in /home/patrick/goalifai/app/models/users_model.py:379]
2025-07-15 23:54:22,247 - app - ERROR - An error occurred while creating the education record - [in /home/patrick/goalifai/app/api/v1/education.py:42]
2025-07-15 23:54:45,825 - app - ERROR - Error creating education record: 'UUID' object has no attribute '_sa_instance_state' - [in /home/patrick/goalifai/app/models/users_model.py:379]
2025-07-15 23:54:45,826 - app - ERROR - An error occurred while creating the education record - [in /home/patrick/goalifai/app/api/v1/education.py:42]
2025-07-15 23:55:02,247 - app - ERROR - Error creating education record: 'UUID' object has no attribute '_sa_instance_state' - [in /home/patrick/goalifai/app/models/users_model.py:379]
2025-07-15 23:55:02,247 - app - ERROR - An error occurred while creating the education record - [in /home/patrick/goalifai/app/api/v1/education.py:42]
2025-07-16 00:05:51,439 - app - INFO - Education record for user b53164c4-7510-4c68-9641-499353facd90 created successfully - [in /home/patrick/goalifai/app/api/v1/education.py:44]
2025-07-16 00:05:51,443 - app - ERROR - An error occurred: Object of type Degree is not JSON serializable - [in /home/patrick/goalifai/app/api/v1/education.py:51]
2025-07-16 00:05:51,444 - app - ERROR - Traceback (most recent call last):
  File "/home/patrick/goalifai/app/api/v1/education.py", line 45, in create_education
    return jsonify({
           ^^^^^^^^^
  File "/home/patrick/goalifai/local-engine/lib/python3.12/site-packages/flask/json/__init__.py", line 170, in jsonify
    return current_app.json.response(*args, **kwargs)  # type: ignore[return-value]
           ^^^^^^^^^^^^^^^^^^^^^^^^^^^^^^^^^^^^^^^^^^
  File "/home/patrick/goalifai/local-engine/lib/python3.12/site-packages/flask/json/provider.py", line 214, in response
    f"{self.dumps(obj, **dump_args)}\n", mimetype=self.mimetype
       ^^^^^^^^^^^^^^^^^^^^^^^^^^^^
  File "/home/patrick/goalifai/local-engine/lib/python3.12/site-packages/flask/json/provider.py", line 179, in dumps
    return json.dumps(obj, **kwargs)
           ^^^^^^^^^^^^^^^^^^^^^^^^^
  File "/usr/lib/python3.12/json/__init__.py", line 238, in dumps
    **kw).encode(obj)
          ^^^^^^^^^^^
  File "/usr/lib/python3.12/json/encoder.py", line 202, in encode
    chunks = list(chunks)
             ^^^^^^^^^^^^
  File "/usr/lib/python3.12/json/encoder.py", line 432, in _iterencode
    yield from _iterencode_dict(o, _current_indent_level)
  File "/usr/lib/python3.12/json/encoder.py", line 406, in _iterencode_dict
    yield from chunks
  File "/usr/lib/python3.12/json/encoder.py", line 406, in _iterencode_dict
    yield from chunks
  File "/usr/lib/python3.12/json/encoder.py", line 439, in _iterencode
    o = _default(o)
        ^^^^^^^^^^^
  File "/home/patrick/goalifai/local-engine/lib/python3.12/site-packages/flask/json/provider.py", line 121, in _default
    raise TypeError(f"Object of type {type(o).__name__} is not JSON serializable")
TypeError: Object of type Degree is not JSON serializable
 - [in /home/patrick/goalifai/app/api/v1/education.py:52]
2025-07-16 00:09:07,258 - app - INFO - Education record for user b53164c4-7510-4c68-9641-499353facd90 created successfully - [in /home/patrick/goalifai/app/api/v1/education.py:44]
2025-07-16 00:10:10,365 - app - INFO - Education record for user b53164c4-7510-4c68-9641-499353facd90 created successfully - [in /home/patrick/goalifai/app/api/v1/education.py:44]
2025-07-16 00:13:02,031 - app - INFO - Education record for user b53164c4-7510-4c68-9641-499353facd90 and degree 390222d6-0419-4679-8e4f-d2885257e512 already exists - [in /home/patrick/goalifai/app/api/v1/education.py:35]
2025-07-16 00:19:43,511 - app - INFO - Retrieved 4 education records - [in /home/patrick/goalifai/app/api/v1/education.py:134]
2025-07-16 00:19:43,511 - app - ERROR - An error occurred: Object of type Degree is not JSON serializable - [in /home/patrick/goalifai/app/api/v1/education.py:140]
2025-07-16 00:19:43,512 - app - ERROR - Traceback (most recent call last):
  File "/home/patrick/goalifai/app/api/v1/education.py", line 135, in list_all_educations
    return jsonify({
           ^^^^^^^^^
  File "/home/patrick/goalifai/local-engine/lib/python3.12/site-packages/flask/json/__init__.py", line 170, in jsonify
    return current_app.json.response(*args, **kwargs)  # type: ignore[return-value]
           ^^^^^^^^^^^^^^^^^^^^^^^^^^^^^^^^^^^^^^^^^^
  File "/home/patrick/goalifai/local-engine/lib/python3.12/site-packages/flask/json/provider.py", line 214, in response
    f"{self.dumps(obj, **dump_args)}\n", mimetype=self.mimetype
       ^^^^^^^^^^^^^^^^^^^^^^^^^^^^
  File "/home/patrick/goalifai/local-engine/lib/python3.12/site-packages/flask/json/provider.py", line 179, in dumps
    return json.dumps(obj, **kwargs)
           ^^^^^^^^^^^^^^^^^^^^^^^^^
  File "/usr/lib/python3.12/json/__init__.py", line 238, in dumps
    **kw).encode(obj)
          ^^^^^^^^^^^
  File "/usr/lib/python3.12/json/encoder.py", line 202, in encode
    chunks = list(chunks)
             ^^^^^^^^^^^^
  File "/usr/lib/python3.12/json/encoder.py", line 432, in _iterencode
    yield from _iterencode_dict(o, _current_indent_level)
  File "/usr/lib/python3.12/json/encoder.py", line 406, in _iterencode_dict
    yield from chunks
  File "/usr/lib/python3.12/json/encoder.py", line 326, in _iterencode_list
    yield from chunks
  File "/usr/lib/python3.12/json/encoder.py", line 406, in _iterencode_dict
    yield from chunks
  File "/usr/lib/python3.12/json/encoder.py", line 439, in _iterencode
    o = _default(o)
        ^^^^^^^^^^^
  File "/home/patrick/goalifai/local-engine/lib/python3.12/site-packages/flask/json/provider.py", line 121, in _default
    raise TypeError(f"Object of type {type(o).__name__} is not JSON serializable")
TypeError: Object of type Degree is not JSON serializable
 - [in /home/patrick/goalifai/app/api/v1/education.py:141]
2025-07-16 00:21:04,892 - app - INFO - Retrieved 4 education records - [in /home/patrick/goalifai/app/api/v1/education.py:134]
2025-07-16 00:21:04,892 - app - ERROR - An error occurred: Object of type Degree is not JSON serializable - [in /home/patrick/goalifai/app/api/v1/education.py:140]
2025-07-16 00:21:04,893 - app - ERROR - Traceback (most recent call last):
  File "/home/patrick/goalifai/app/api/v1/education.py", line 135, in list_all_educations
    return jsonify({
           ^^^^^^^^^
  File "/home/patrick/goalifai/local-engine/lib/python3.12/site-packages/flask/json/__init__.py", line 170, in jsonify
    return current_app.json.response(*args, **kwargs)  # type: ignore[return-value]
           ^^^^^^^^^^^^^^^^^^^^^^^^^^^^^^^^^^^^^^^^^^
  File "/home/patrick/goalifai/local-engine/lib/python3.12/site-packages/flask/json/provider.py", line 214, in response
    f"{self.dumps(obj, **dump_args)}\n", mimetype=self.mimetype
       ^^^^^^^^^^^^^^^^^^^^^^^^^^^^
  File "/home/patrick/goalifai/local-engine/lib/python3.12/site-packages/flask/json/provider.py", line 179, in dumps
    return json.dumps(obj, **kwargs)
           ^^^^^^^^^^^^^^^^^^^^^^^^^
  File "/usr/lib/python3.12/json/__init__.py", line 238, in dumps
    **kw).encode(obj)
          ^^^^^^^^^^^
  File "/usr/lib/python3.12/json/encoder.py", line 202, in encode
    chunks = list(chunks)
             ^^^^^^^^^^^^
  File "/usr/lib/python3.12/json/encoder.py", line 432, in _iterencode
    yield from _iterencode_dict(o, _current_indent_level)
  File "/usr/lib/python3.12/json/encoder.py", line 406, in _iterencode_dict
    yield from chunks
  File "/usr/lib/python3.12/json/encoder.py", line 326, in _iterencode_list
    yield from chunks
  File "/usr/lib/python3.12/json/encoder.py", line 406, in _iterencode_dict
    yield from chunks
  File "/usr/lib/python3.12/json/encoder.py", line 439, in _iterencode
    o = _default(o)
        ^^^^^^^^^^^
  File "/home/patrick/goalifai/local-engine/lib/python3.12/site-packages/flask/json/provider.py", line 121, in _default
    raise TypeError(f"Object of type {type(o).__name__} is not JSON serializable")
TypeError: Object of type Degree is not JSON serializable
 - [in /home/patrick/goalifai/app/api/v1/education.py:141]
2025-07-16 00:21:19,583 - app - INFO - Retrieved 4 education records - [in /home/patrick/goalifai/app/api/v1/education.py:134]
2025-07-16 00:21:19,584 - app - ERROR - An error occurred: Object of type Degree is not JSON serializable - [in /home/patrick/goalifai/app/api/v1/education.py:140]
2025-07-16 00:21:19,585 - app - ERROR - Traceback (most recent call last):
  File "/home/patrick/goalifai/app/api/v1/education.py", line 135, in list_all_educations
    return jsonify({
           ^^^^^^^^^
  File "/home/patrick/goalifai/local-engine/lib/python3.12/site-packages/flask/json/__init__.py", line 170, in jsonify
    return current_app.json.response(*args, **kwargs)  # type: ignore[return-value]
           ^^^^^^^^^^^^^^^^^^^^^^^^^^^^^^^^^^^^^^^^^^
  File "/home/patrick/goalifai/local-engine/lib/python3.12/site-packages/flask/json/provider.py", line 214, in response
    f"{self.dumps(obj, **dump_args)}\n", mimetype=self.mimetype
       ^^^^^^^^^^^^^^^^^^^^^^^^^^^^
  File "/home/patrick/goalifai/local-engine/lib/python3.12/site-packages/flask/json/provider.py", line 179, in dumps
    return json.dumps(obj, **kwargs)
           ^^^^^^^^^^^^^^^^^^^^^^^^^
  File "/usr/lib/python3.12/json/__init__.py", line 238, in dumps
    **kw).encode(obj)
          ^^^^^^^^^^^
  File "/usr/lib/python3.12/json/encoder.py", line 202, in encode
    chunks = list(chunks)
             ^^^^^^^^^^^^
  File "/usr/lib/python3.12/json/encoder.py", line 432, in _iterencode
    yield from _iterencode_dict(o, _current_indent_level)
  File "/usr/lib/python3.12/json/encoder.py", line 406, in _iterencode_dict
    yield from chunks
  File "/usr/lib/python3.12/json/encoder.py", line 326, in _iterencode_list
    yield from chunks
  File "/usr/lib/python3.12/json/encoder.py", line 406, in _iterencode_dict
    yield from chunks
  File "/usr/lib/python3.12/json/encoder.py", line 439, in _iterencode
    o = _default(o)
        ^^^^^^^^^^^
  File "/home/patrick/goalifai/local-engine/lib/python3.12/site-packages/flask/json/provider.py", line 121, in _default
    raise TypeError(f"Object of type {type(o).__name__} is not JSON serializable")
TypeError: Object of type Degree is not JSON serializable
 - [in /home/patrick/goalifai/app/api/v1/education.py:141]
2025-07-16 00:22:02,574 - app - INFO - Retrieved 4 education records - [in /home/patrick/goalifai/app/api/v1/education.py:134]
2025-07-16 00:23:44,424 - app - INFO - Retrieved 4 education records - [in /home/patrick/goalifai/app/api/v1/education.py:134]
2025-07-16 00:23:50,935 - app - INFO - Retrieved 4 education records - [in /home/patrick/goalifai/app/api/v1/education.py:134]
2025-07-16 00:24:58,987 - app - INFO - Retrieved 4 education records - [in /home/patrick/goalifai/app/api/v1/education.py:134]
2025-07-16 00:28:09,174 - app - INFO - Education record e7767f5a-04f8-486f-9447-8f8efd9682b4 updated successfully - [in /home/patrick/goalifai/app/api/v1/education.py:81]
2025-07-16 00:28:27,736 - app - INFO - Education record e7767f5a-04f8-486f-9447-8f8efd9682b4 updated successfully - [in /home/patrick/goalifai/app/api/v1/education.py:81]
2025-07-16 00:28:39,562 - app - INFO - Retrieved 4 education records - [in /home/patrick/goalifai/app/api/v1/education.py:134]
2025-07-16 00:30:32,084 - app - INFO - Education record 1ccaf9b5-f483-435c-9fad-857a900955ae deleted successfully - [in /home/patrick/goalifai/app/api/v1/education.py:98]
2025-07-16 00:30:45,136 - app - INFO - Retrieved 3 education records - [in /home/patrick/goalifai/app/api/v1/education.py:134]
2025-07-16 00:31:32,872 - app - INFO - Retrieved 3 education records - [in /home/patrick/goalifai/app/api/v1/education.py:135]
2025-07-16 00:32:05,908 - app - INFO - Retrieved 3 education records - [in /home/patrick/goalifai/app/api/v1/education.py:134]
2025-07-16 00:32:42,840 - app - INFO - Education record 03542d5d-a331-4c7d-800d-0a63b1340446 deleted successfully - [in /home/patrick/goalifai/app/api/v1/education.py:98]
2025-07-16 00:32:50,798 - app - INFO - Retrieved 2 education records - [in /home/patrick/goalifai/app/api/v1/education.py:134]
2025-07-21 01:01:04,759 - app - INFO - Retrieved 2 education records - [in /home/patrick/goalifai/app/api/v1/education.py:134]
2025-07-21 02:06:10,666 - app - ERROR - An error occurred while loading categories from file: [Errno 2] No such file or directory: '/files/default_categories.json' - [in /home/patrick/goalifai/app/api/v1/categories.py:108]
2025-07-21 02:07:13,928 - app - ERROR - An error occurred while loading categories from file: [Errno 2] No such file or directory: '/app/files/default_categories.json' - [in /home/patrick/goalifai/app/api/v1/categories.py:108]
2025-07-21 02:07:26,321 - app - ERROR - An error occurred while loading categories from file: [Errno 2] No such file or directory: '/goalifai/app/files/default_categories.json' - [in /home/patrick/goalifai/app/api/v1/categories.py:108]
2025-07-21 02:07:49,974 - app - ERROR - An error occurred while loading categories from file: [Errno 2] No such file or directory: '/app/files/default_categories.json' - [in /home/patrick/goalifai/app/api/v1/categories.py:108]
2025-07-21 02:08:51,251 - app - ERROR - An error occurred while loading categories from file: [Errno 2] No such file or directory: 'files/default_categories.json' - [in /home/patrick/goalifai/app/api/v1/categories.py:108]
2025-07-21 02:08:57,615 - app - ERROR - An error occurred while loading categories from file: [Errno 2] No such file or directory: '/files/default_categories.json' - [in /home/patrick/goalifai/app/api/v1/categories.py:108]
2025-07-21 02:10:30,076 - app - ERROR - An error occurred while loading categories from file: [Errno 2] No such file or directory: '/files/default_categories.json' - [in /home/patrick/goalifai/app/api/v1/categories.py:108]
2025-07-22 22:49:14,239 - app - INFO - Retrieved 2 education records - [in /home/patrick/goalifai/app/api/v1/education.py:134]
2025-07-22 23:00:36,668 - app - INFO - Category Taxes and returns updated successfully - [in /home/patrick/goalifai/app/api/v1/categories.py:74]
2025-07-22 23:05:11,908 - app - INFO - Category Taxes updated successfully - [in /home/patrick/goalifai/app/api/v1/categories.py:74]
2025-07-22 23:07:59,472 - app - INFO - Category Taxes deleted successfully - [in /home/patrick/goalifai/app/api/v1/categories.py:164]
2025-07-22 23:10:37,486 - app - INFO - Category Savings deleted successfully - [in /home/patrick/goalifai/app/api/v1/categories.py:164]
2025-07-22 23:13:26,319 - app - INFO - Category Taxes updated successfully - [in /home/patrick/goalifai/app/api/v1/categories.py:74]
2025-07-22 23:13:40,092 - app - INFO - Category Taxes deleted successfully - [in /home/patrick/goalifai/app/api/v1/categories.py:164]
2025-07-23 09:02:36,272 - app - INFO - Education record e7767f5a-04f8-486f-9447-8f8efd9682b4 updated successfully - [in /home/patrick/goalifai/app/api/v1/education.py:81]
2025-07-26 10:58:31,778 - app - ERROR - Error while deleting goal status: type object 'GoalStatus' has no attribute 'delete_status' - [in /home/patrick/goalifai/app/api/v1/goal_priorities.py:61]
2025-07-26 11:09:10,223 - app - INFO - Error while adding goal status (psycopg2.errors.UniqueViolation) duplicate key value violates unique constraint "goal_statuses_name_key"
DETAIL:  Key (name)=(1234) already exists.

[SQL: INSERT INTO goal_statuses (status_id, name) VALUES (%(status_id)s::UUID, %(name)s)]
[parameters: {'status_id': UUID('fa4e5348-c0f4-40d4-8ee3-bca1973f56e2'), 'name': 1234}]
(Background on this error at: https://sqlalche.me/e/20/gkpj) - [in /home/patrick/goalifai/app/models/central.py:191]
2025-07-26 11:12:08,143 - app - INFO - Error while adding goal status (psycopg2.errors.UniqueViolation) duplicate key value violates unique constraint "goal_statuses_name_key"
DETAIL:  Key (name)=(1234) already exists.

[SQL: INSERT INTO goal_statuses (status_id, name) VALUES (%(status_id)s::UUID, %(name)s)]
[parameters: {'status_id': UUID('799a86c4-f5ff-41b4-95e7-3755c89df3c4'), 'name': 1234}]
(Background on this error at: https://sqlalche.me/e/20/gkpj) - [in /home/patrick/goalifai/app/models/central.py:191]
2025-07-26 11:14:43,775 - app - INFO - Error while adding goal status (psycopg2.errors.UniqueViolation) duplicate key value violates unique constraint "goal_statuses_name_key"
DETAIL:  Key (name)=(1234) already exists.

[SQL: INSERT INTO goal_statuses (status_id, name) VALUES (%(status_id)s::UUID, %(name)s)]
[parameters: {'status_id': UUID('541695d4-beeb-4f99-86de-5331edd0c2bc'), 'name': 1234}]
(Background on this error at: https://sqlalche.me/e/20/gkpj) - [in /home/patrick/goalifai/app/models/central.py:191]
2025-07-26 11:27:29,828 - app - INFO - Goal status Suprise created successfully - [in /home/patrick/goalifai/app/api/v1/goal_status.py:22]
2025-08-28 19:41:57,277 - app - ERROR - An error occurred: User.create_user() missing 1 required positional argument: 'education_level' - [in /home/patrick/goalifai/app/api/v1/client/users.py:56]
2025-08-28 19:41:57,278 - app - ERROR - Traceback (most recent call last):
  File "/home/patrick/goalifai/app/api/v1/client/users.py", line 26, in create_user
    user = User.create_user(
           ^^^^^^^^^^^^^^^^^
TypeError: User.create_user() missing 1 required positional argument: 'education_level'
 - [in /home/patrick/goalifai/app/api/v1/client/users.py:57]
2025-08-28 22:07:46,070 - app - INFO - User testuser@example.com created successfully - [in /home/patrick/goalifai/app/api/v1/client/users.py:39]
2025-08-28 22:07:46,076 - app - ERROR - An error occurred: 'NoneType' object has no attribute 'strftime' - [in /home/patrick/goalifai/app/api/v1/client/users.py:55]
2025-08-28 22:07:46,077 - app - ERROR - Traceback (most recent call last):
  File "/home/patrick/goalifai/app/api/v1/client/users.py", line 47, in create_user
    "date_of_birth": user.date_of_birth.strftime("%Y-%m-%d"),
                     ^^^^^^^^^^^^^^^^^^^^^^^^^^^
AttributeError: 'NoneType' object has no attribute 'strftime'
 - [in /home/patrick/goalifai/app/api/v1/client/users.py:56]
2025-08-29 21:01:32,057 - app - ERROR - An error occurred: 'NoneType' object has no attribute 'strftime' - [in /home/patrick/goalifai/app/api/v1/client/users.py:91]
2025-08-29 21:01:32,061 - app - ERROR - Traceback (most recent call last):
  File "/home/patrick/goalifai/app/api/v1/client/users.py", line 73, in users_list
    "date_of_birth": user.date_of_birth.strftime("%Y-%m-%d"),
                     ^^^^^^^^^^^^^^^^^^^^^^^^^^^
AttributeError: 'NoneType' object has no attribute 'strftime'
 - [in /home/patrick/goalifai/app/api/v1/client/users.py:92]
2025-08-29 21:14:01,107 - app - ERROR - An error occurred: 'NoneType' object has no attribute 'strftime' - [in /home/patrick/goalifai/app/api/v1/client/users.py:90]
2025-08-29 21:14:01,110 - app - ERROR - Traceback (most recent call last):
  File "/home/patrick/goalifai/app/api/v1/client/users.py", line 73, in users_list
    "date_of_birth": user.date_of_birth.strftime("%Y-%m-%d") ,
                     ^^^^^^^^^^^^^^^^^^^^^^^^^^^
AttributeError: 'NoneType' object has no attribute 'strftime'
 - [in /home/patrick/goalifai/app/api/v1/client/users.py:91]
